# Scheduler Log - Started at time 1
# Algorithm: 2, Quantum: -1
At time 11 process 1 arrived arr 11 total 8 remain 8 wait 0
At time 11 process 1 started arr 11 total 8 remain 8 wait 0
At time 13 process 2 arrived arr 13 total 4 remain 4 wait 0
At time 13 process 1 stopped arr 11 total 8 remain 6 wait 2
At time 13 process 2 started arr 13 total 4 remain 4 wait 0
At time 17 process 2 finished arr 13 total 4 remain 0 wait -1 TA 4 WTA 1.00
At time 17 process 1 resumed arr 11 total 8 remain 6 wait 4
At time 19 process 3 arrived arr 19 total 1 remain 1 wait 0
At time 19 process 4 arrived arr 19 total 23 remain 23 wait 0
At time 19 process 1 stopped arr 11 total 8 remain 4 wait 2
At time 19 process 3 started arr 19 total 1 remain 1 wait 0
At time 20 process 3 finished arr 19 total 1 remain 0 wait -1 TA 1 WTA 1.00
At time 20 process 1 resumed arr 11 total 8 remain 4 wait 1
At time 23 process 5 arrived arr 23 total 14 remain 14 wait 0
At time 24 process 1 finished arr 11 total 8 remain 0 wait 8 TA 13 WTA 1.62
At time 24 process 5 started arr 23 total 14 remain 14 wait 1
At time 30 process 6 arrived arr 30 total 20 remain 20 wait 0
At time 31 process 7 arrived arr 31 total 15 remain 15 wait 0
At time 32 process 8 arrived arr 32 total 24 remain 24 wait 0
At time 38 process 5 finished arr 23 total 14 remain 0 wait 0 TA 15 WTA 1.07
At time 38 process 7 started arr 31 total 15 remain 15 wait 7
At time 42 process 9 arrived arr 42 total 29 remain 29 wait 0
At time 49 process 10 arrived arr 49 total 4 remain 4 wait 0
At time 53 process 7 finished arr 31 total 15 remain 0 wait 6 TA 22 WTA 1.47
At time 53 process 10 started arr 49 total 4 remain 4 wait 4
At time 57 process 10 finished arr 49 total 4 remain 0 wait 3 TA 8 WTA 2.00
At time 57 process 6 started arr 30 total 20 remain 20 wait 27
At time 77 process 6 finished arr 30 total 20 remain 0 wait 26 TA 47 WTA 2.35
At time 77 process 4 started arr 19 total 23 remain 23 wait 58
At time 100 process 4 finished arr 19 total 23 remain 0 wait 57 TA 81 WTA 3.52
At time 100 process 8 started arr 32 total 24 remain 24 wait 68
At time 124 process 8 finished arr 32 total 24 remain 0 wait 67 TA 92 WTA 3.83
At time 124 process 9 started arr 42 total 29 remain 29 wait 82
At time 153 process 9 finished arr 42 total 29 remain 0 wait 81 TA 111 WTA 3.83
