# Scheduler start at time 0
# algo=2, quantum=-1
At time 11 process 1 arrived arr 11 total 8 remain 8 wait 0
At time 11 process 2 arrived arr 11 total 5 remain 5 wait 0
At time 11 process 2 started arr 11 total 5 remain 5 wait 0
At time 16 process 2 finished arr 11 total 5 remain 0 wait 0 TA 5 WTA 1.00
At time 16 process 1 started arr 11 total 8 remain 8 wait 5
At time 19 process 3 arrived arr 19 total 3 remain 3 wait 0
At time 19 process 4 arrived arr 19 total 4 remain 4 wait 0
At time 19 process 1 stopped arr 11 total 8 remain 5 wait 3
At time 19 process 3 started arr 19 total 3 remain 3 wait 0
At time 22 process 3 finished arr 19 total 3 remain 0 wait 0 TA 3 WTA 1.00
At time 22 process 4 started arr 19 total 4 remain 4 wait 3
At time 23 process 5 arrived arr 23 total 2 remain 2 wait 0
At time 23 process 4 stopped arr 19 total 4 remain 3 wait 1
At time 23 process 5 started arr 23 total 2 remain 2 wait 0
At time 25 process 5 finished arr 23 total 2 remain 0 wait 0 TA 2 WTA 1.00
At time 25 process 4 resumed arr 19 total 4 remain 3 wait 2
At time 28 process 4 finished arr 19 total 4 remain 0 wait 5 TA 9 WTA 2.25
At time 28 process 1 resumed arr 11 total 8 remain 5 wait 9
At time 30 process 6 arrived arr 30 total 6 remain 6 wait 0
At time 31 process 7 arrived arr 31 total 1 remain 1 wait 0
At time 31 process 1 stopped arr 11 total 8 remain 2 wait 3
At time 31 process 7 started arr 31 total 1 remain 1 wait 0
At time 32 process 8 arrived arr 32 total 5 remain 5 wait 0
At time 32 process 7 finished arr 31 total 1 remain 0 wait 0 TA 1 WTA 1.00
At time 32 process 1 resumed arr 11 total 8 remain 2 wait 1
At time 34 process 1 finished arr 11 total 8 remain 0 wait 15 TA 23 WTA 2.88
At time 34 process 8 started arr 32 total 5 remain 5 wait 2
At time 39 process 8 finished arr 32 total 5 remain 0 wait 2 TA 7 WTA 1.40
At time 39 process 6 started arr 30 total 6 remain 6 wait 9
At time 42 process 9 arrived arr 42 total 3 remain 3 wait 0
At time 45 process 6 finished arr 30 total 6 remain 0 wait 9 TA 15 WTA 2.50
At time 45 process 9 started arr 42 total 3 remain 3 wait 3
At time 48 process 9 finished arr 42 total 3 remain 0 wait 3 TA 6 WTA 2.00
At time 49 process 10 arrived arr 49 total 4 remain 4 wait 0
At time 49 process 10 started arr 49 total 4 remain 4 wait 0
At time 53 process 10 finished arr 49 total 4 remain 0 wait 0 TA 4 WTA 1.00
