# Scheduler start at time 0
# algo=2, quantum=-1
At time 11 process 1 arrived arr 11 total 8 remain 8 wait 0
At time 11 process 2 arrived arr 11 total 28 remain 28 wait 0
At time 11 process 1 started arr 11 total 8 remain 8 wait 0
At time 19 process 3 arrived arr 19 total 21 remain 21 wait 0
At time 19 process 4 arrived arr 19 total 23 remain 23 wait 0
At time 19 process 1 finished arr 11 total 8 remain 0 wait 1543562032 TA 8 WTA 1.00
At time 19 process 3 started arr 19 total 21 remain 21 wait 0
At time 23 process 5 arrived arr 23 total 14 remain 14 wait 0
At time 23 process 3 stopped arr 19 total 21 remain 17 wait 4
At time 23 process 5 started arr 23 total 14 remain 14 wait 0
At time 30 process 6 arrived arr 30 total 20 remain 20 wait 0
At time 31 process 7 arrived arr 31 total 15 remain 15 wait 0
At time 32 process 8 arrived arr 32 total 24 remain 24 wait 0
At time 37 process 5 finished arr 23 total 14 remain 0 wait 1543562032 TA 14 WTA 1.00
At time 37 process 7 started arr 31 total 15 remain 15 wait 6
At time 42 process 9 arrived arr 42 total 29 remain 29 wait 0
At time 49 process 10 arrived arr 49 total 4 remain 4 wait 0
At time 52 process 7 finished arr 31 total 15 remain 0 wait 1543562038 TA 21 WTA 1.40
At time 52 process 10 started arr 49 total 4 remain 4 wait 3
At time 56 process 10 finished arr 49 total 4 remain 0 wait 1543562035 TA 7 WTA 1.75
At time 56 process 3 resumed arr 19 total 21 remain 17 wait 33
At time 73 process 3 finished arr 19 total 21 remain 0 wait 1543562069 TA 54 WTA 2.57
At time 73 process 6 started arr 30 total 20 remain 20 wait 43
At time 93 process 6 finished arr 30 total 20 remain 0 wait 1543562075 TA 63 WTA 3.15
At time 93 process 4 started arr 19 total 23 remain 23 wait 74
At time 116 process 4 finished arr 19 total 23 remain 0 wait 1543562106 TA 97 WTA 4.22
At time 116 process 8 started arr 32 total 24 remain 24 wait 84
At time 140 process 8 finished arr 32 total 24 remain 0 wait 1543562116 TA 108 WTA 4.50
At time 140 process 2 started arr 11 total 28 remain 28 wait 129
At time 168 process 2 finished arr 11 total 28 remain 0 wait 1543562161 TA 157 WTA 5.61
At time 168 process 9 started arr 42 total 29 remain 29 wait 126
At time 197 process 9 finished arr 42 total 29 remain 0 wait 1543562158 TA 155 WTA 5.34
